<?xml version="1.0"?>
<robot name="simplebot_v10">
	<link name="body_v1:1">
		<inertial>
			<mass value="0.6270135399067726"/>
			<origin rpy="0 0 0" xyz="0.0 -1.6368194021527588e-16 0.02501302876295383"/>
			<inertia ixx="0.00021449841499530944" ixy="0.0" ixz="0.0" iyy="0.00021436713359791843" iyz="-8.268457026766289e-19" izz="0.00016733489203919717"/>
		</inertial>
		<collision>
			<origin rpy="0.0 -0.0 0.0" xyz="0.0 0.0 0.0"/>
			<geometry>
				<mesh filename="./meshes/body_v1.stl" scale="0.001 0.001 0.001"/>
			</geometry>
		</collision>
		<visual>
			<origin rpy="0.0 -0.0 0.0" xyz="0.0 0.0 0.0"/>
			<geometry>
				<mesh filename="./meshes/body_v1.stl" scale="0.001 0.001 0.001"/>
			</geometry>
		</visual>
	</link>
	<link name="arm_v4:1">
		<inertial>
			<mass value="0.08563600411415896"/>
			<origin rpy="0 0 0" xyz="0.020000108108964253 -1.2777236801930768e-09 -0.044000010082646465"/>
			<inertia ixx="6.047178013888332e-05" ixy="-1.1761736486478386e-10" ixz="-2.4124275950221375e-10" iyy="7.574938670418301e-05" iyz="-1.8657195267730814e-12" izz="1.6637926888581922e-05"/>
		</inertial>
		<collision>
			<origin rpy="0.0 -1.5313421029312503e-16 0.0" xyz="0.019999999999999993 0.005 -0.044"/>
			<geometry>
				<mesh filename="./meshes/arm_v4.stl" scale="0.001 0.001 0.001"/>
			</geometry>
		</collision>
		<visual>
			<origin rpy="0.0 -1.5313421029312503e-16 0.0" xyz="0.019999999999999993 0.005 -0.044"/>
			<geometry>
				<mesh filename="./meshes/arm_v4.stl" scale="0.001 0.001 0.001"/>
			</geometry>
		</visual>
	</link>
	<link name="arm_v4:2">
		<inertial>
			<mass value="0.08563600411415896"/>
			<origin rpy="0 0 0" xyz="-0.01999989189103574 -1.2777236801930768e-09 -0.044000010082646465"/>
			<inertia ixx="6.047178013888332e-05" ixy="-1.1761736486478384e-10" ixz="-2.4124275951331596e-10" iyy="7.574938670418301e-05" iyz="-1.865719526773046e-12" izz="1.6637926888581922e-05"/>
		</inertial>
		<collision>
			<origin rpy="0.0 1.5313421029312507e-16 0.0" xyz="-0.02 0.005 -0.044"/>
			<geometry>
				<mesh filename="./meshes/arm_v4.stl" scale="0.001 0.001 0.001"/>
			</geometry>
		</collision>
		<visual>
			<origin rpy="0.0 1.5313421029312507e-16 0.0" xyz="-0.02 0.005 -0.044"/>
			<geometry>
				<mesh filename="./meshes/arm_v4.stl" scale="0.001 0.001 0.001"/>
			</geometry>
		</visual>
	</link>
	<link name="arm_v4:3">
		<inertial>
			<mass value="0.08563600411415896"/>
			<origin rpy="0 0 0" xyz="0.015000108108964304 -1.2777236801930768e-09 -0.04400001008264644"/>
			<inertia ixx="6.0471780138883525e-05" ixy="-1.1761736486478386e-10" ixz="-2.412427594578048e-10" iyy="7.574938670418305e-05" iyz="-1.865719526773187e-12" izz="1.66379268885819e-05"/>
		</inertial>
		<collision>
			<origin rpy="0.0 -1.0395456967976374e-15 0.0" xyz="0.015000000000000045 0.005 -0.043999999999999984"/>
			<geometry>
				<mesh filename="./meshes/arm_v4.stl" scale="0.001 0.001 0.001"/>
			</geometry>
		</collision>
		<visual>
			<origin rpy="0.0 -1.0395456967976374e-15 0.0" xyz="0.015000000000000045 0.005 -0.043999999999999984"/>
			<geometry>
				<mesh filename="./meshes/arm_v4.stl" scale="0.001 0.001 0.001"/>
			</geometry>
		</visual>
	</link>
	<link name="arm_v4:4">
		<inertial>
			<mass value="0.08563600411415896"/>
			<origin rpy="0 0 0" xyz="-0.014999891891035764 -1.2777236801930768e-09 -0.04400001008264644"/>
			<inertia ixx="6.0471780138883525e-05" ixy="-1.1761736486478386e-10" ixz="-2.412427596354405e-10" iyy="7.574938670418287e-05" iyz="-1.865719526772951e-12" izz="1.6637926888581943e-05"/>
		</inertial>
		<collision>
			<origin rpy="0.0 9.62978591651075e-16 0.0" xyz="-0.01500000000000003 0.005 -0.043999999999999984"/>
			<geometry>
				<mesh filename="./meshes/arm_v4.stl" scale="0.001 0.001 0.001"/>
			</geometry>
		</collision>
		<visual>
			<origin rpy="0.0 9.62978591651075e-16 0.0" xyz="-0.01500000000000003 0.005 -0.043999999999999984"/>
			<geometry>
				<mesh filename="./meshes/arm_v4.stl" scale="0.001 0.001 0.001"/>
			</geometry>
		</visual>
	</link>
	<joint name="rev0" type="revolute">
		<parent link="body_v1:1"/>
		<child link="arm_v4:1"/>
		<origin rpy="0 0 0" xyz="0.020000000000000007 0.0 0.01671866065705706"/>
		<axis xyz="-1.0 0.0 0.0"/>
		<limit effort="10" lower="-1.5707963267948966" upper="1.5707963267948966" velocity="10"/>
	</joint>
	<joint name="rev1" type="revolute">
		<parent link="body_v1:1"/>
		<child link="arm_v4:2"/>
		<origin rpy="0 0 0" xyz="-0.02 0.0 0.01671866065705706"/>
		<axis xyz="1.0 0.0 0.0"/>
		<limit effort="10" lower="-1.5707963267948966" upper="1.5707963267948966" velocity="10"/>

	</joint>
	<joint name="rev2" type="revolute">
		<parent link="arm_v4:1"/>
		<child link="arm_v4:3"/>
		<origin rpy="0 0 0" xyz="0.0 0.0 -0.088"/>
		<axis xyz="1.0 0.0 6.125368411725003e-16"/>
		<limit effort="10" lower="-1.5707963267948966" upper="1.5707963267948966" velocity="10"/>

	</joint>
	<joint name="rev3" type="revolute">
		<parent link="arm_v4:2"/>
		<child link="arm_v4:4"/>
		<origin rpy="0 0 0" xyz="-1.3877787807814457e-17 0.0 -0.088"/>
		<axis xyz="-1.0 0.0 5.359697360259377e-16"/>
		<limit effort="10" lower="-1.5707963267948966" upper="1.5707963267948966" velocity="10"/>
	</joint>
</robot>
