<?xml version="1.0"?>
<robot name="simplebot_v12">
	<link name="body_v2:1">
		<inertial>
			<mass value="0.6270135399067726"/>
			<origin rpy="0 0 0" xyz="-1.6368194021527588e-16 0.0 0.02501302876295383"/>
			<inertia ixx="0.00021436713359791008" ixy="0.0" ixz="-8.268457026766289e-19" iyy="0.00021449841499530126" iyz="0.0" izz="0.00016733489203919717"/>
		</inertial>
		<collision name="body_v2:1_collision">
			<origin rpy="0.0 -0.0 0.0" xyz="0.0 0.0 0.0"/>
			<geometry>
				<mesh filename="./meshes/body_v2.stl" scale="1.0 1.0 1.0"/>
			</geometry>
		</collision>
		<visual name="body_v2:1_visual">
			<origin rpy="0.0 -0.0 0.0" xyz="0.0 0.0 0.0"/>
			<geometry>
				<mesh filename="./meshes/body_v2.stl" scale="1.0 1.0 1.0"/>
			</geometry>
		</visual>
	</link>
	<link name="arm_v5:4">
		<inertial>
			<mass value="0.08672920153779431"/>
			<origin rpy="0 0 0" xyz="5.61973798496318e-09 -0.02000005549761377 -0.04400002004079691"/>
			<inertia ixx="7.579976082038588e-05" ixy="-1.327769300555852e-10" ixz="-9.929237480342638e-12" iyy="6.052090444595709e-05" iyz="2.758813504311064e-11" izz="1.665793336539927e-05"/>
		</inertial>
		<collision name="arm_v5:4_collision">
			<origin rpy="-1.5313421029312507e-16 -0.0 0.0" xyz="-0.005 -0.02 -0.044"/>
			<geometry>
				<mesh filename="./meshes/arm_v5.stl" scale="1.0 1.0 1.0"/>
			</geometry>
		</collision>
		<visual name="arm_v5:4_visual">
			<origin rpy="-1.5313421029312507e-16 -0.0 0.0" xyz="-0.005 -0.02 -0.044"/>
			<geometry>
				<mesh filename="./meshes/arm_v5.stl" scale="1.0 1.0 1.0"/>
			</geometry>
		</visual>
	</link>
	<link name="arm_v5:5">
		<inertial>
			<mass value="0.08672920153779431"/>
			<origin rpy="0 0 0" xyz="5.61973798496318e-09 0.019999944502386225 -0.04400002004079691"/>
			<inertia ixx="7.579976082038588e-05" ixy="-1.327769300555852e-10" ixz="-9.92923748034268e-12" iyy="6.052090444595709e-05" iyz="2.75881350653151e-11" izz="1.665793336539927e-05"/>
		</inertial>
		<collision name="arm_v5:5_collision">
			<origin rpy="1.5313421029312503e-16 -0.0 0.0" xyz="-0.005 0.019999999999999993 -0.044"/>
			<geometry>
				<mesh filename="./meshes/arm_v5.stl" scale="1.0 1.0 1.0"/>
			</geometry>
		</collision>
		<visual name="arm_v5:5_visual">
			<origin rpy="1.5313421029312503e-16 -0.0 0.0" xyz="-0.005 0.019999999999999993 -0.044"/>
			<geometry>
				<mesh filename="./meshes/arm_v5.stl" scale="1.0 1.0 1.0"/>
			</geometry>
		</visual>
	</link>
	<link name="arm_v5:6">
		<inertial>
			<mass value="0.08672920153779431"/>
			<origin rpy="0 0 0" xyz="5.61973798496318e-09 -0.015000055497613716 -0.04400002004079688"/>
			<inertia ixx="7.579976082038495e-05" ixy="-1.3277693005558354e-10" ixz="-9.929237480342469e-12" iyy="6.0520904445956344e-05" iyz="2.758813502090618e-11" izz="1.665793336539927e-05"/>
		</inertial>
		<collision name="arm_v5:6_collision">
			<origin rpy="-9.62978591651072e-16 2.9508961634435116e-36 5.505714157152939e-21" xyz="-0.0049999999999999715 -0.014999999999999947 -0.043999999999999984"/>
			<geometry>
				<mesh filename="./meshes/arm_v5.stl" scale="1.0 1.0 1.0"/>
			</geometry>
		</collision>
		<visual name="arm_v5:6_visual">
			<origin rpy="-9.62978591651072e-16 2.9508961634435116e-36 5.505714157152939e-21" xyz="-0.0049999999999999715 -0.014999999999999947 -0.043999999999999984"/>
			<geometry>
				<mesh filename="./meshes/arm_v5.stl" scale="1.0 1.0 1.0"/>
			</geometry>
		</visual>
	</link>
	<link name="arm_v5:7">
		<inertial>
			<mass value="0.08672920153779431"/>
			<origin rpy="0 0 0" xyz="5.61973798496318e-09 0.014999944502386248 -0.04400002004079688"/>
			<inertia ixx="7.579976082038549e-05" ixy="-1.3277693005558458e-10" ixz="-9.929237480342782e-12" iyy="6.0520904445956704e-05" iyz="2.758813510972402e-11" izz="1.665793336539927e-05"/>
		</inertial>
		<collision name="arm_v5:7_collision">
			<origin rpy="1.0395456967976358e-15 -1.232242353965429e-36 2.0117032497289618e-21" xyz="-0.004999999999999989 0.015000000000000017 -0.043999999999999984"/>
			<geometry>
				<mesh filename="./meshes/arm_v5.stl" scale="1.0 1.0 1.0"/>
			</geometry>
		</collision>
		<visual name="arm_v5:7_visual">
			<origin rpy="1.0395456967976358e-15 -1.232242353965429e-36 2.0117032497289618e-21" xyz="-0.004999999999999989 0.015000000000000017 -0.043999999999999984"/>
			<geometry>
				<mesh filename="./meshes/arm_v5.stl" scale="1.0 1.0 1.0"/>
			</geometry>
		</visual>
	</link>
	<joint name="rev0" type="continuous">
		<parent link="body_v2:1"/>
		<child link="arm_v5:4"/>
		<origin rpy="0 0 0" xyz="0.0 -0.02 0.01671866065705706"/>
		<axis xyz="0.0 1.0 0.0"/>
	</joint>
	<joint name="rev1" type="continuous">
		<parent link="arm_v5:4"/>
		<child link="arm_v5:6"/>
		<origin rpy="0 0 0" xyz="0.0 -2.7755575615628914e-17 -0.088"/>
		<axis xyz="0.0 -1.0 5.359697360259377e-16"/>
	</joint>
	<joint name="rev2" type="continuous">
		<parent link="body_v2:1"/>
		<child link="arm_v5:5"/>
		<origin rpy="0 0 0" xyz="0.0 0.020000000000000007 0.01671866065705706"/>
		<axis xyz="0.0 -1.0 0.0"/>
	</joint>
	<joint name="rev3" type="continuous">
		<parent link="arm_v5:5"/>
		<child link="arm_v5:7"/>
		<origin rpy="0 0 0" xyz="0.0 0.0 -0.088"/>
		<axis xyz="0.0 1.0 6.125368411725003e-16"/>
	</joint>
</robot>
